Workbook

Sheet Tổng quan
A1: BẢNG ĐIỀU KHIỂN DỰ ÁN GMRAG2
A2: GraphRAG multi-tenant self-host: Keycloak OIDC, RLS thật, ResourceBAC, Qdrant collection-per-tenant, Redis worker, Ollama embedding.
A4: Chỉ số | B4: Giá trị | F4: Luồng | G4: Tổng task | H4: Hoàn thành
A5: Tổng số task | B5: =COUNTA('Kế hoạch Task'!$A$6:$A$90) -> 85 | F5: ='Timeline 2 tuần'!A5 -> 1 | G5: ='Timeline 2 tuần'!D5 -> 8 | H5: ='Timeline 2 tuần'!E5 -> 8
A6: Hoàn thành | B6: =COUNTIF('Kế hoạch Task'!$K$6:$K$90,"Hoàn thành") -> 72 | F6: ='Timeline 2 tuần'!A6 -> 2 | G6: ='Timeline 2 tuần'!D6 -> 10 | H6: ='Timeline 2 tuần'!E6 -> 10
A7: Đang làm | B7: =COUNTIF('Kế hoạch Task'!$K$6:$K$90,"Đang làm") -> 0 | F7: ='Timeline 2 tuần'!A7 -> 3 | G7: ='Timeline 2 tuần'!D7 -> 8 | H7: ='Timeline 2 tuần'!E7 -> 8
A8: Rủi ro | B8: =COUNTIF('Kế hoạch Task'!$K$6:$K$90,"Rủi ro") -> 0 | F8: ='Timeline 2 tuần'!A8 -> 4 | G8: ='Timeline 2 tuần'!D8 -> 7 | H8: ='Timeline 2 tuần'!E8 -> 7
A9: Chưa bắt đầu | B9: =COUNTIF('Kế hoạch Task'!$K$6:$K$90,"Chưa bắt đầu") -> 13 | F9: ='Timeline 2 tuần'!A9 -> 5 | G9: ='Timeline 2 tuần'!D9 -> 10 | H9: ='Timeline 2 tuần'!E9 -> 10
A10: Tiến độ chung | B10: =IF(B5=0,0,B6/B5) -> 0.84705882 | F10: ='Timeline 2 tuần'!A10 -> 6 | G10: ='Timeline 2 tuần'!D10 -> 8 | H10: ='Timeline 2 tuần'!E10 -> 8
A11: Khung kế hoạch | B11: 2 tuần: 17/06-30/06 | F11: ='Timeline 2 tuần'!A11 -> 7 | G11: ='Timeline 2 tuần'!D11 -> 12 | H11: ='Timeline 2 tuần'!E11 -> 12
F12: ='Timeline 2 tuần'!A12 -> 8 | G12: ='Timeline 2 tuần'!D12 -> 7 | H12: ='Timeline 2 tuần'!E12 -> 7
A13: Phạm vi chính | F13: ='Timeline 2 tuần'!A13 -> 9 | G13: ='Timeline 2 tuần'!D13 -> 9 | H13: ='Timeline 2 tuần'!E13 -> 1
A14: Hạng mục | B14: Mục tiêu quản lý | C14: Theo dõi ở sheet | D14: Ghi chú | F14: ='Timeline 2 tuần'!A14 -> 10 | G14: ='Timeline 2 tuần'!D14 -> 6 | H14: ='Timeline 2 tuần'!E14 -> 1
A15: Hạ tầng | B15: 9 services docker-compose gồm Keycloak | C15: Kế hoạch Task | D15: Sprint 1
A16: Backend lõi | B16: Config, DB pool, error envelope | C16: Kế hoạch Task | D16: Sprint 1-2
A17: Auth/RLS | B17: TenantContext, SET LOCAL, policy | C17: Kế hoạch Task | D17: Sprint 2-3 | F17: Nguyên tắc điều hành
A18: Qdrant | B18: Collection-per-tenant, chunks + graph | C18: Kế hoạch Task | D18: Sprint 4 | F18: 1 | G18: Ưu tiên task P0 trước và khóa scope hằng ngày.
A19: Worker | B19: Redis ingestion pipeline | C19: Kế hoạch Task | D19: Sprint 5 | F19: 2 | G19: Bắt buộc self-host: dùng Keycloak cho AuthN/OIDC, không dùng auth SaaS.
A20: RAG/LLM | B20: BYOK, DeepSeek, retrieval, citation | C20: Kế hoạch Task | D20: Sprint 6 | F20: 3 | G20: Mọi task đi theo TDD: test đỏ trước, triển khai tối thiểu, test xanh, commit riêng.
A21: API | B21: Tenant-scoped routes + ResourceBAC | C21: Kế hoạch Task | D21: Sprint 7-8 | F21: 4 | G21: Mọi query nghiệp vụ phải đi qua TenantContext; không lấy tenant UUID từ URL để xử lý business logic.
A22: Frontend | B22: Khung Next.js và component mẫu | C22: Kế hoạch Task | D22: Sprint 9 | F22: 5 | G22: RLS là lớp bảo vệ bắt buộc ở DB; backend chỉ là lớp kiểm soát bổ sung.
A23: Vận hành | B23: E2E, pentest RLS, backup, smoke test | C23: Timeline 2 tuần | D23: Sprint 10 | F23: 6 | G23: Vector lưu ở Qdrant; PostgreSQL chỉ giữ metadata và quan hệ nghiệp vụ.

Sheet Kế hoạch Task
A1: KẾ HOẠCH TASK GMRAG2
A2: Tracker TDD cho 82 task trong khung 2 tuần từ 17/06/2026 đến 30/06/2026. Vẫn giữ sprint gốc để truy vết phạm vi plan.
A4: Quy ước TDD: viết test đỏ → chạy để FAIL → triển khai tối thiểu → chạy PASS → commit riêng cho từng task.
A5: Mã | B5: Sprint | C5: Nhóm | D5: Công việc | E5: Mục tiêu/đầu ra | F5: Khu vực chính | G5: Loại việc | H5: Ưu tiên | I5: Phụ thuộc | J5: Chủ sở hữu | K5: Trạng thái | L5: % hoàn thành | M5: Bắt đầu | N5: Hạn hoàn thành | O5: Test đỏ | P5: Triển khai | Q5: Test xanh | R5: Commit | S5: Kiểm thử/verify | T5: Ghi chú
A6: T1 | B6: 1 | C6: Hạ tầng | D6: Khởi tạo monorepo gmrag2/ + git init + README + .gitignore | E6: Hạ tầng: Khởi tạo monorepo gmrag2/ + git init + README + .gitignore | F6: gmrag2/ + infra/ + backend/ + frontend/ | G6: Hạ tầng | H6: P0 - Chặn đường găng | J6: Backend Dev | K6: Hoàn thành | L6: =IF(K6="Hoàn thành",1,IF(K6="Đang làm",0.5,IF(K6="Rủi ro",0.25,IF(K6="Tạm dừng",0.1,0)))) -> 1 | M6: 46190 | N6: 46191 | O6: Hoàn tất | P6: Hoàn tất | Q6: Hoàn tất | R6: Hoàn tất | S6: docker compose config && kiểm tra healthcheck
A7: T2 | B7: 1 | C7: Hạ tầng | D7: infra/docker-compose.yml với 9 services self-host (postgres16, qdrant, minio, redis, ollama, keycloak, backend, worker, frontend) + healthchecks | E7: Hạ tầng: infra/docker-compose.yml với 9 services self-host (postgres16, qdrant, minio, redis, ollama, keycloak, backend, worker, frontend) + healthchecks | F7: infra/docker-compose.yml | G7: Hạ tầng | H7: P0 - Chặn đường găng | I7: T1 | J7: Backend Dev | K7: Hoàn thành | L7: =IF(K7="Hoàn thành",1,IF(K7="Đang làm",0.5,IF(K7="Rủi ro",0.25,IF(K7="Tạm dừng",0.1,0)))) -> 1 | M7: 46190 | N7: 46191 | O7: Hoàn tất | P7: Hoàn tất | Q7: Hoàn tất | R7: Hoàn tất | S7: docker compose config && kiểm tra healthcheck
A8: T3 | B8: 1 | C8: Hạ tầng | D8: infra/postgres/init.sql + infra/minio/init.sh (tạo bucket gmrag-uploads) | E8: Hạ tầng: infra/postgres/init.sql + infra/minio/init.sh (tạo bucket gmrag-uploads) | F8: infra/postgres/init.sql | G8: Hạ tầng | H8: P1 - Cao | I8: T2 | J8: Backend Dev | K8: Hoàn thành | L8: =IF(K8="Hoàn thành",1,IF(K8="Đang làm",0.5,IF(K8="Rủi ro",0.25,IF(K8="Tạm dừng",0.1,0)))) -> 1 | M8: 46190 | N8: 46191 | O8: Hoàn tất | P8: Hoàn tất | Q8: Hoàn tất | R8: Hoàn tất | S8: docker compose config && kiểm tra healthcheck
A9: T4 | B9: 1 | C9: Hạ tầng | D9: .env.example với mọi env var (DATABASE_URL, KEYCLOAK_ISSUER, KEYCLOAK_CLIENT_ID, DEEPSEEK_, QDRANT_URL, S3_, REDIS_URL, OLLAMA_, GMRAG_, CORS_*) | E9: Hạ tầng: .env.example với mọi env var (DATABASE_URL, KEYCLOAK_ISSUER, KEYCLOAK_CLIENT_ID, DEEPSEEK_, QDRANT_URL, S3_, REDIS_URL, OLLAMA_, GMRAG_, CORS_*) | F9: .env.example | G9: Hạ tầng | H9: P0 - Chặn đường găng | I9: T3 | J9: Backend Dev | K9: Hoàn thành | L9: =IF(K9="Hoàn thành",1,IF(K9="Đang làm",0.5,IF(K9="Rủi ro",0.25,IF(K9="Tạm dừng",0.1,0)))) -> 1 | M9: 46190 | N9: 46191 | O9: Hoàn tất | P9: Hoàn tất | Q9: Hoàn tất | R9: Hoàn tất | S9: docker compose config && kiểm tra healthcheck
A10: T5 | B10: 1 | C10: Hạ tầng | D10: Backend Rust workspace Cargo.toml (members: core, api, worker) | E10: Hạ tầng: Backend Rust workspace Cargo.toml (members: core, api, worker) | F10: gmrag2/ + infra/ + backend/ + frontend/ | G10: Hạ tầng | H10: P0 - Chặn đường găng | I10: T4 | J10: Backend Dev | K10: Hoàn thành | L10: =IF(K10="Hoàn thành",1,IF(K10="Đang làm",0.5,IF(K10="Rủi ro",0.25,IF(K10="Tạm dừng",0.1,0)))) -> 1 | M10: 46191 | N10: 46192 | O10: Hoàn tất | P10: Hoàn tất | Q10: Hoàn tất | R10: Hoàn tất | S10: Kiểm tra thủ công theo checklist
A11: T6 | B11: 1 | C11: Hạ tầng | D11: backend/crates/core/ skeleton (Config struct đọc env, Error enum, DbPool helper) | E11: Hạ tầng: backend/crates/core/ skeleton (Config struct đọc env, Error enum, DbPool helper) | F11: gmrag2/ + infra/ + backend/ + frontend/ | G11: Hạ tầng | H11: P1 - Cao | I11: T5 | J11: Backend Dev | K11: Hoàn thành | L11: =IF(K11="Hoàn thành",1,IF(K11="Đang làm",0.5,IF(K11="Rủi ro",0.25,IF(K11="Tạm dừng",0.1,0)))) -> 1 | M11: 46191 | N11: 46192 | O11: Hoàn tất | P11: Hoàn tất | Q11: Hoàn tất | R11: Hoàn tất | S11: Kiểm tra thủ công theo checklist
A12: T7 | B12: 1 | C12: Hạ tầng | D12: backend/crates/api/ skeleton: main.rs boot pool+migrate+health endpoint, chạy được cargo run | E12: Hạ tầng: backend/crates/api/ skeleton: main.rs boot pool+migrate+health endpoint, chạy được cargo run | F12: gmrag2/ + infra/ + backend/ + frontend/ | G12: Hạ tầng | H12: P1 - Cao | I12: T6 | J12: Backend Dev | K12: Hoàn thành | L12: =IF(K12="Hoàn thành",1,IF(K12="Đang làm",0.5,IF(K12="Rủi ro",0.25,IF(K12="Tạm dừng",0.1,0)))) -> 1 | M12: 46191 | N12: 46192 | O12: Hoàn tất | P12: Hoàn tất | Q12: Hoàn tất | R12: Hoàn tất | S12: cargo run -p gmrag-api && GET /health
A13: T8 | B13: 1 | C13: Hạ tầng | D13: Frontend package.json + next dev chạy được trang / trống | E13: Hạ tầng: Frontend package.json + next dev chạy được trang / trống | F13: gmrag2/ + infra/ + backend/ + frontend/ | G13: Hạ tầng | H13: P2 - Trung bình | I13: T7 | J13: Frontend Dev | K13: Hoàn thành | L13: =IF(K13="Hoàn thành",1,IF(K13="Đang làm",0.5,IF(K13="Rủi ro",0.25,IF(K13="Tạm dừng",0.1,0)))) -> 1 | M13: 46191 | N13: 46192 | O13: Hoàn tất | P13: Hoàn tất | Q13: Hoàn tất | R13: Hoàn tất | S13: pnpm install && pnpm dev
A14: T9 | B14: 2 | C14: Định danh & Tenant | D14: core/src/config.rs + test parse env (TDD) | E14: Hoàn thành theo TDD: core/src/config.rs + test parse env (TDD) | F14: backend/crates/api/src/auth + middleware + migrations | G14: Backend | H14: P0 - Chặn đường găng | I14: T1-T8 | J14: Backend Dev | K14: Hoàn thành | L14: =IF(K14="Hoàn thành",1,IF(K14="Đang làm",0.5,IF(K14="Rủi ro",0.25,IF(K14="Tạm dừng",0.1,0)))) -> 1 | M14: 46191 | N14: 46192 | O14: Hoàn tất | P14: Hoàn tất | Q14: Hoàn tất | R14: Hoàn tất | S14: cargo test --workspace
A15: T10 | B15: 2 | C15: Định danh & Tenant | D15: api/src/auth/jwt.rs validate Keycloak OIDC JWT + JWKS cache + test với mock JWKS | E15: Hoàn thành theo TDD: api/src/auth/jwt.rs validate Keycloak OIDC JWT + JWKS cache + test với mock JWKS | F15: api/src/auth/jwt.rs | G15: Backend API | H15: P1 - Cao | I15: T9 | J15: Backend Dev | K15: Hoàn thành | L15: =IF(K15="Hoàn thành",1,IF(K15="Đang làm",0.5,IF(K15="Rủi ro",0.25,IF(K15="Tạm dừng",0.1,0)))) -> 1 | M15: 46191 | N15: 46192 | O15: Hoàn tất | P15: Hoàn tất | Q15: Hoàn tất | R15: Hoàn tất | S15: cargo test --workspace
A16: T11 | B16: 2 | C16: Định danh & Tenant | D16: api/src/auth/extractor.rs AuthUser (port) + test | E16: Hoàn thành theo TDD: api/src/auth/extractor.rs AuthUser (port) + test | F16: api/src/auth/extractor.rs | G16: Backend API | H16: P1 - Cao | I16: T10 | J16: Backend Dev | K16: Hoàn thành | L16: =IF(K16="Hoàn thành",1,IF(K16="Đang làm",0.5,IF(K16="Rủi ro",0.25,IF(K16="Tạm dừng",0.1,0)))) -> 1 | M16: 46191 | N16: 46192 | O16: Hoàn tất | P16: Hoàn tất | Q16: Hoàn tất | R16: Hoàn tất | S16: cargo test --workspace
A17: T12 | B17: 2 | C17: Định danh & Tenant | D17: Migrations: tenants, tenant_members, users, platform_admins (DDL đầy đủ trong plan) | E17: Định danh & Tenant: Migrations: tenants, tenant_members, users, platform_admins (DDL đầy đủ trong plan) | F17: backend/crates/api/src/auth + middleware + migrations | G17: Database/Bảo mật | H17: P0 - Chặn đường găng | I17: T11 | J17: Backend Dev | K17: Hoàn thành | L17: =IF(K17="Hoàn thành",1,IF(K17="Đang làm",0.5,IF(K17="Rủi ro",0.25,IF(K17="Tạm dừng",0.1,0)))) -> 1 | M17: 46191 | N17: 46192 | O17: Hoàn tất | P17: Hoàn tất | Q17: Hoàn tất | R17: Hoàn tất | S17: cargo test --workspace
A18: T13 | B18: 2 | C18: Định danh & Tenant | D18: api/src/auth/tenant.rs TenantContext extractor (đọc X-Tenant-Id + validate membership) + test | E18: Hoàn thành theo TDD: api/src/auth/tenant.rs TenantContext extractor (đọc X-Tenant-Id + validate membership) + test | F18: api/src/auth/tenant.rs | G18: Backend API | H18: P0 - Chặn đường găng | I18: T12 | J18: Backend Dev | K18: Hoàn thành | L18: =IF(K18="Hoàn thành",1,IF(K18="Đang làm",0.5,IF(K18="Rủi ro",0.25,IF(K18="Tạm dừng",0.1,0)))) -> 1 | M18: 46192 | N18: 46193 | O18: Hoàn tất | P18: Hoàn tất | Q18: Hoàn tất | R18: Hoàn tất | S18: cargo test --workspace
... A23: T18 | B23: 2 | C23: Định danh & Tenant | D23: GET /users/me trả tenants[] + test integration | E23: Hoàn thành theo TDD: GET /users/me trả tenants[] + test integration | F23: backend/crates/api/src/auth + middleware + migrations | G23: Backend | H23: P1 - Cao | I23: T17 | J23: Backend Dev | K23: Hoàn thành | L23: =IF(K23="Hoàn thành",1,IF(K23="Đang làm",0.5,IF(K23="Rủi ro",0.25,IF(K23="Tạm dừng",0.1,0)))) -> 1 | M23: 46193 | N23: 46194 | O23: Hoàn tất | P23: Hoàn tất | Q23: Hoàn tất | R23: Hoàn tất | S23: cargo test --workspace
A24: T19 | B24: 3 | C24: Cơ sở dữ liệu | D24: Migrations workspaces + workspace_members (owner_id, tenant_id FK) | E24: Cơ sở dữ liệu: Migrations workspaces + workspace_members (owner_id, tenant_id FK) | F24: backend/crates/api/migrations | G24: Database/Bảo mật | H24: P0 - Chặn đường găng | I24: T12-T15 | J24: Backend Dev | K24: Hoàn thành | L24: =IF(K24="Hoàn thành",1,IF(K24="Đang làm",0.5,IF(K24="Rủi ro",0.25,IF(K24="Tạm dừng",0.1,0)))) -> 1 | M24: 46193 | N24: 46194 | O24: Hoàn tất | P24: Hoàn tất | Q24: Hoàn tất | R24: Hoàn tất | S24: cargo test --workspace | T24: Lồng ghép xử lý Blocker 1 & 2 từ BATCH2B: Phải refactor TenantContext thành middleware chạy trước RLS, và chuyển DB connection pool từ role superuser (gmrag) sang role gmrag_app để đảm bảo RLS thực sự có hiệu lực trước khi thêm bảng mới
A25: T20 | B25: 3 | C25: Cơ sở dữ liệu | D25: Migrations documents (owner_id, visibility, share_token) + document_chunks (qdrant_point_id, KHÔNG embedding) | E25: Cơ sở dữ liệu: Migrations documents (owner_id, visibility, share_token) + document_chunks (qdrant_point_id, KHÔNG embedding) | F25: backend/crates/api/migrations | G25: Database/Bảo mật | H25: P1 - Cao | I25: T19 | J25: Backend Dev | K25: Hoàn thành | L25: =IF(K25="Hoàn thành",1,IF(K25="Đang làm",0.5,IF(K25="Rủi ro",0.25,IF(K25="Tạm dừng",0.1,0)))) -> 1 | M25: 46193 | N25: 46194 | O25: Hoàn tất | P25: Hoàn tất | Q25: Hoàn tất | R25: Hoàn tất | S25: cargo test --workspace
A26: T21 | B26: 3 | C26: Cơ sở dữ liệu | D26: Migrations graph_* (+contributor_id, qdrant_point_id) | E26: Cơ sở dữ liệu: Migrations graph_* (+contributor_id, qdrant_point_id) | F26: backend/crates/api/migrations | G26: Database/Bảo mật | H26: P1 - Cao | I26: T20 | J26: Backend Dev | K26: Hoàn thành | L26: =IF(K26="Hoàn thành",1,IF(K26="Đang làm",0.5,IF(K26="Rủi ro",0.25,IF(K26="Tạm dừng",0.1,0)))) -> 1 | M26: 46193 | N26: 46194 | O26: Hoàn tất | P26: Hoàn tất | Q26: Hoàn tất | R26: Hoàn tất | S26: cargo test --workspace
A27: T22 | B27: 3 | C27: Cơ sở dữ liệu | D27: Migrations chat_sessions (+owner_id, visibility) + chat_messages | E27: Cơ sở dữ liệu: Migrations chat_sessions (+owner_id, visibility) + chat_messages | F27: backend/crates/api/migrations | G27: Database/Bảo mật | H27: P1 - Cao | I27: T21 | J27: Backend Dev | K27: Hoàn thành | L27: =IF(K27="Hoàn thành",1,IF(K27="Đang làm",0.5,IF(K27="Rủi ro",0.25,IF(K27="Tạm dừng",0.1,0)))) -> 1 | M27: 46193 | N27: 46194 | O27: Hoàn tất | P27: Hoàn tất | Q27: Hoàn tất | R27: Hoàn tất | S27: cargo test --workspace
A28: T23 | B28: 3 | C28: Cơ sở dữ liệu | D28: Migrations resource_acl + invitations | E28: Cơ sở dữ liệu: Migrations resource_acl + invitations | F28: backend/crates/api/migrations | G28: Database/Bảo mật | H28: P1 - Cao | I28: T22 | J28: Backend Dev | K28: Hoàn thành | L28: =IF(K28="Hoàn thành",1,IF(K28="Đang làm",0.5,IF(K28="Rủi ro",0.25,IF(K28="Tạm dừng",0.1,0)))) -> 1 | M28: 46194 | N28: 46195 | O28: Hoàn tất | P28: Hoàn tất | Q28: Hoàn tất | R28: Hoàn tất | S28: cargo test --workspace
A29: T24 | B29: 3 | C29: Cơ sở dữ liệu | D29: Migrations tenant_quotas + usage_events + audit_log + ingest_jobs | E29: Cơ sở dữ liệu: Migrations tenant_quotas + usage_events + audit_log + ingest_jobs | F29: backend/crates/api/migrations | G29: Database/Bảo mật | H29: P0 - Chặn đường găng | I29: T23 | J29: Backend Dev | K29: Hoàn thành | L29: =IF(K29="Hoàn thành",1,IF(K29="Đang làm",0.5,IF(K29="Rủi ro",0.25,IF(K29="Tạm dừng",0.1,0)))) -> 1 | M29: 46194 | N29: 46195 | O29: Hoàn tất | P29: Hoàn tất | Q29: Hoàn tất | R29: Hoàn tất | S29: cargo test --workspace
A30: T25 | B30: 3 | C30: Cơ sở dữ liệu | D30: RLS policy apply trên TẤT cả bảng có tenant_id (migration) + test negative isolation | E30: Hoàn thành theo TDD: RLS policy apply trên TẤT cả bảng có tenant_id (migration) + test negative isolation | F30: backend/crates/api/migrations | G30: Database/Bảo mật | H30: P0 - Chặn đường găng | I30: T24 | J30: Backend Dev | K30: Hoàn thành | L30: =IF(K30="Hoàn thành",1,IF(K30="Đang làm",0.5,IF(K30="Rủi ro",0.25,IF(K30="Tạm dừng",0.1,0)))) -> 1 | M30: 46194 | N30: 46195 | O30: Hoàn tất | P30: Hoàn tất | Q30: Hoàn tất | R30: Hoàn tất | S30: cargo test --workspace
A31: T26 | B31: 3 | C31: Cơ sở dữ liệu | D31: Seed script infra/postgres/seed.sql (2 tenants, users, sample workspace) | E31: Cơ sở dữ liệu: Seed script infra/postgres/seed.sql (2 tenants, users, sample workspace) | F31: infra/postgres/seed.sql | G31: Database/Bảo mật | H31: P2 - Trung bình | I31: T25 | J31: Backend Dev | K31: Hoàn thành | L31: =IF(K31="Hoàn thành",1,IF(K31="Đang làm",0.5,IF(K31="Rủi ro",0.25,IF(K31="Tạm dừng",0.1,0)))) -> 1 | M31: 46194 | N31: 46195 | O31: Hoàn tất | P31: Hoàn tất | Q31: Hoàn tất | R31: Hoàn tất | S31: cargo test --workspace | T31: Lưu ý DB đang áp dụng bless checksum cho 2 file migration cũ, lệnh migrate có thể cần dọn dẹp offline cache. Các bài test negative isolation cross-tenant phải tiếp tục sử dụng SET LOCAL ROLE gmrag_app
A32: T27 | B32: 4 | C32: Vector DB | D32: core thêm qdrant-client dep + QdrantStore wrapper (create/delete collection, upsert/search) | E32: Vector DB: core thêm qdrant-client dep + QdrantStore wrapper (create/delete collection, upsert/search) | F32: backend/crates/core/src/qdrant + Qdrant | G32: Vector DB | H32: P0 - Chặn đường găng | I32: T19-T26 | J32: Backend Dev | K32: Hoàn thành | L32: =IF(K32="Hoàn thành",1,IF(K32="Đang làm",0.5,IF(K32="Rủi ro",0.25,IF(K32="Tạm dừng",0.1,0)))) -> 1 | M32: 46194 | N32: 46195 | O32: Hoàn tất | P32: Hoàn tất | Q32: Hoàn tất | R32: Hoàn tất | S32: cargo test --workspace
A33: T28 | B33: 4 | C33: Vector DB | D33: Collection schema: chunks_{tenant_id} dim 768 HNSW cosine + payload {workspace_id, document_id, chunk_index, filename, owner_id, visibility} | E33: Vector DB: Collection schema: chunks_{tenant_id} dim 768 HNSW cosine + payload {workspace_id, document_id, chunk_index, filename, owner_id, visibility} | F33: backend/crates/core/src/qdrant + Qdrant | G33: Vector DB | H33: P0 - Chặn đường găng | I33: T27 | J33: Backend Dev | K33: Hoàn thành | L33: =IF(K33="Hoàn thành",1,IF(K33="Đang làm",0.5,IF(K33="Rủi ro",0.25,IF(K33="Tạm dừng",0.1,0)))) -> 1 | M33: 46194 | N33: 46195 | O33: Hoàn tất | P33: Hoàn tất | Q33: Hoàn tất | R33: Hoàn tất | S33: cargo test --workspace
A34: T29 | B34: 4 | C34: Vector DB | D34: Collection schema: graph_{tenant_id} dim 768 + payload {node_id, workspace_id, entity_name} | E34: Vector DB: Collection schema: graph_{tenant_id} dim 768 + payload {node_id, workspace_id, entity_name} | F34: backend/crates/core/src/qdrant + Qdrant | G34: Vector DB | H34: P1 - Cao | I34: T28 | J34: Backend Dev | K34: Hoàn thành | L34: =IF(K34="Hoàn thành",1,IF(K34="Đang làm",0.5,IF(K34="Rủi ro",0.25,IF(K34="Tạm dừng",0.1,0)))) -> 1 | M34: 46194 | N34: 46195 | O34: Hoàn tất | P34: Hoàn tất | Q34: Hoàn tất | R34: Hoàn tất | S34: cargo test --workspace
A35: T30 | B35: 4 | C35: Vector DB | D35: Lifecycle hook: create tenant → tạo 2 collection; delete tenant → xóa collection + test | E35: Hoàn thành theo TDD: Lifecycle hook: create tenant → tạo 2 collection; delete tenant → xóa collection + test | F35: backend/crates/core/src/qdrant + Qdrant | G35: Vector DB | H35: P0 - Chặn đường găng | I35: T29 | J35: Backend Dev | K35: Hoàn thành | L35: =IF(K35="Hoàn thành",1,IF(K35="Đang làm",0.5,IF(K35="Rủi ro",0.25,IF(K35="Tạm dừng",0.1,0)))) -> 1 | M35: 46194 | N35: 46195 | O35: Hoàn tất | P35: Hoàn tất | Q35: Hoàn tất | R35: Hoàn tất | S35: cargo test --workspace | T35: Trước khi tạo collection theo tenant, phải đổi default Qdrant sang gRPC port 6334 (DEFAULT_QDRANT_URL, .env.example). create_chunks_collection/create_graph_collection hiện không idempotent, lifecycle hook cần check list_collection_names hoặc thêm ensure_* wrapper trước khi create.
A36: T31 | B36: 4 | C36: Vector DB | D36: QdrantStore::upsert_chunks(tenant, points) + test | E36: Hoàn thành theo TDD: QdrantStore::upsert_chunks(tenant, points) + test | F36: backend/crates/core/src/qdrant + Qdrant | G36: Vector DB | H36: P1 - Cao | I36: T30 | J36: Backend Dev | K36: Hoàn thành | L36: =IF(K36="Hoàn thành",1,IF(K36="Đang làm",0.5,IF(K36="Rủi ro",0.25,IF(K36="Tạm dừng",0.1,0)))) -> 1 | M36: 46195 | N36: 46196 | O36: Hoàn tất | P36: Hoàn tất | Q36: Hoàn tất | R36: Hoàn tất | S36: cargo test --workspace
A37: T32 | B37: 4 | C37: Vector DB | D37: QdrantStore::search_chunks(tenant, vector, filter, top_k) + test recall | E37: Hoàn thành theo TDD: QdrantStore::search_chunks(tenant, vector, filter, top_k) + test recall | F37: backend/crates/core/src/qdrant + Qdrant | G37: Vector DB | H37: P1 - Cao | I37: T31 | J37: Backend Dev | K37: Hoàn thành | L37: =IF(K37="Hoàn thành",1,IF(K37="Đang làm",0.5,IF(K37="Rủi ro",0.25,IF(K37="Tạm dừng",0.1,0)))) -> 1 | M37: 46195 | N37: 46196 | O37: Hoàn tất | P37: Hoàn tất | Q37: Hoàn tất | R37: Hoàn tất | S37: cargo test --workspace | T37: < Thêm hotfix. 2 dòng fix clippy. Tạo tenant_resolve_middleware mới, wire đúng thứ tự LIFO của Axum. Nhớ là Axum layer stack ngược — .layer() gọi sau = chạy trước. Nếu wire sai thứ tự là 500 hết. Tách admin_pool (superuser, chỉ dùng cho migration + provision) với app_pool (gmrag_app, RLS enforced, dùng cho mọi business query). Worker Batch 5 PHẢI dùng app_pool không thì data bypass RLS bay màu không hay :)
A38: T33 | B38: 4 | C38: Vector DB | D38: QdrantStore::search_graph_nodes + upsert_graph + test | E38: Hoàn thành theo TDD: QdrantStore::search_graph_nodes + upsert_graph + test | F38: backend/crates/core/src/qdrant + Qdrant | G38: Vector DB | H38: P2 - Trung bình | I38: T32 | J38: Backend Dev | K38: Hoàn thành | L38: =IF(K38="Hoàn thành",1,IF(K38="Đang làm",0.5,IF(K38="Rủi ro",0.25,IF(K38="Tạm dừng",0.1,0)))) -> 1 | M38: 46195 | N38: 46196 | O38: Hoàn tất | P38: Hoàn tất | Q38: Hoàn tất | R38: Hoàn tất | S38: cargo test --workspace | T38: T29 mới chỉ tạo schema graph_{tenant_id}. Khi implement upsert/search graph nodes cần embed entity description, filter theo workspace_id, và giữ node_id để join ngược về graph_nodes trong Postgres.
A39: T34 | B39: 5 | C39: Worker ingestion | D39: worker/ crate skeleton + Redis poll loop (BRPOP gmrag:ingest_jobs) + test với redis mock | E39: Hoàn thành theo TDD: worker/ crate skeleton + Redis poll loop (BRPOP gmrag:ingest_jobs) + test với redis mock | F39: backend/crates/worker/src | G39: Worker | H39: P0 - Chặn đường găng | I39: T1-T8, T27-T33 | J39: Backend Dev | K39: Hoàn thành | L39: =IF(K39="Hoàn thành",1,IF(K39="Đang làm",0.5,IF(K39="Rủi ro",0.25,IF(K39="Tạm dừng",0.1,0)))) -> 1 | M39: 46195 | N39: 46196 | O39: Hoàn tất | P39: Hoàn tất | Q39: Hoàn tất | R39: Hoàn tất | S39: cargo test -p gmrag-worker | T39: CẢNH BÁO KIẾN TRÚC TỪ T19: Worker hiện đang dùng init_pool (superuser). Khi xử lý ingest pipeline, worker bắt buộc phải chuyển sang dùng init_app_pool và thực thi SET LOCAL app.tenant_id = ... cho từng job cụ thể trước khi ghi metadata vào Postgres, nếu không data sẽ bypass RLS hoặc bị chặn.
A40: T35 | B40: 5 | C40: Worker ingestion | D40: worker/src/storage.rs S3 download/upload (MinIO) + test | E40: Hoàn thành theo TDD: worker/src/storage.rs S3 download/upload (MinIO) + test | F40: worker/src/storage.rs | G40: Worker | H40: P1 - Cao | I40: T34 | J40: Backend Dev | K40: Hoàn thành | L40: =IF(K40="Hoàn thành",1,IF(K40="Đang làm",0.5,IF(K40="Rủi ro",0.25,IF(K40="Tạm dừng",0.1,0)))) -> 1 | M40: 46195 | N40: 46196 | O40: Hoàn tất | P40: Hoàn tất | Q40: Hoàn tất | R40: Hoàn tất | S40: cargo test -p gmrag-worker
A41: T36 | B41: 5 | C41: Worker ingestion | D41: worker/src/pdf_parser.rs port lopdf+pdf-extract + timeout + test với sample PDF | E41: Hoàn thành theo TDD: worker/src/pdf_parser.rs port lopdf+pdf-extract + timeout + test với sample PDF | F41: worker/src/pdf_parser.rs | G41: Worker | H41: P1 - Cao | I41: T35 | J41: Backend Dev | K41: Hoàn thành | L41: =IF(K41="Hoàn thành",1,IF(K41="Đang làm",0.5,IF(K41="Rủi ro",0.25,IF(K41="Tạm dừng",0.1,0)))) -> 1 | M41: 46195 | N41: 46196 | O41: Hoàn tất | P41: Hoàn tất | Q41: Hoàn tất | R41: Hoàn tất | S41: cargo test -p gmrag-worker
A42: T37 | B42: 5 | C42: Worker ingestion | D42: worker/src/pdf_parser.rs OCR fallback thật (pdfium-render rasterize) + test | E42: Hoàn thành theo TDD: worker/src/pdf_parser.rs OCR fallback thật (pdfium-render rasterize) + test | F42: worker/src/pdf_parser.rs | G42: Worker | H42: P2 - Trung bình | I42: T36 | J42: Backend Dev | K42: Hoàn thành | L42: =IF(K42="Hoàn thành",1,IF(K42="Đang làm",0.5,IF(K42="Rủi ro",0.25,IF(K42="Tạm dừng",0.1,0)))) -> 1 | M42: 46195 | N42: 46196 | O42: Hoàn tất | P42: Hoàn tất | Q42: Hoàn tất | R42: Hoàn tất | S42: cargo test -p gmrag-worker
A43: T38 | B43: 5 | C43: Worker ingestion | D43: worker/src/chunking.rs port tiktoken cl100k 1200/100 + test | E43: Hoàn thành theo TDD: worker/src/chunking.rs port tiktoken cl100k 1200/100 + test | F43: worker/src/chunking.rs | G43: Worker | H43: P1 - Cao | I43: T37 | J43: Backend Dev | K43: Hoàn thành | L43: =IF(K43="Hoàn thành",1,IF(K43="Đang làm",0.5,IF(K43="Rủi ro",0.25,IF(K43="Tạm dừng",0.1,0)))) -> 1 | M43: 46196 | N43: 46197 | O43: Hoàn tất | P43: Hoàn tất | Q43: Hoàn tất | R43: Hoàn tất | S43: cargo test -p gmrag-worker
A44: T39 | B44: 5 | C44: Worker ingestion | D44: worker/src/embedding.rs Ollama embed batch + retry/backoff + test (mock Ollama) | E44: Hoàn thành theo TDD: worker/src/embedding.rs Ollama embed batch + retry/backoff + test (mock Ollama) | F44: worker/src/embedding.rs | G44: Worker | H44: P0 - Chặn đường găng | I44: T38 | J44: Backend Dev | K44: Hoàn thành | L44: =IF(K44="Hoàn thành",1,IF(K44="Đang làm",0.5,IF(K44="Rủi ro",0.25,IF(K44="Tạm dừng",0.1,0)))) -> 1 | M44: 46196 | N44: 46197 | O44: Hoàn tất | P44: Hoàn tất | Q44: Hoàn tất | R44: Hoàn tất | S44: cargo test -p gmrag-worker
A45: T40 | B45: 5 | C45: Worker ingestion | D45: BYOK embed trait: đọc tenant_llm_config, nếu có OpenAI key → dùng text-embedding-3-small + test | E45: Hoàn thành theo TDD: BYOK embed trait: đọc tenant_llm_config, nếu có OpenAI key → dùng text-embedding-3-small + test | F45: backend/crates/worker/src | G45: Worker | H45: P1 - Cao | I45: T39 | J45: Backend Dev | K45: Hoàn thành | L45: =IF(K45="Hoàn thành",1,IF(K45="Đang làm",0.5,IF(K45="Rủi ro",0.25,IF(K45="Tạm dừng",0.1,0)))) -> 1 | M45: 46196 | N45: 46197 | O45: Hoàn tất | P45: Hoàn tất | Q45: Hoàn tất | R45: Hoàn tất | S45: cargo test -p gmrag-worker
...

Sheet Timeline 2 tuần
A1: TIMELINE 2 TUẦN
A2: Kế hoạch được nén trong 14 ngày từ 17/06/2026 đến 30/06/2026. Các sprint bên dưới là sprint gốc/luồng phạm vi từ plan ban đầu.
A4: Sprint gốc | B4: Tên luồng | C4: Nhóm | D4: Số task | E4: Hoàn thành | F4: Đang làm | G4: Rủi ro | H4: % hoàn thành | I4: Bắt đầu | J4: Kết thúc | K4: Đầu ra chính | L4: Ngày 1 17/06 | M4: Ngày 2 18/06 | N4: Ngày 3 19/06 | O4: Ngày 4 20/06 | P4: Ngày 5 21/06 | Q4: Ngày 6 22/06 | R4: Ngày 7 23/06 | S4: Ngày 8 24/06 | T4: Ngày 9 25/06 | U4: Ngày 10 26/06 | V4: Ngày 11 27/06 | W4: Ngày 12 28/06 | X4: Ngày 13 29/06 | Y4: Ngày 14 30/06
A5: 1 | B5: Hạ tầng & khởi tạo monorepo | C5: Hạ tầng | D5: =COUNTIF('Kế hoạch Task'!$B$6:$B$90,A5) -> 8 | E5: =COUNTIFS('Kế hoạch Task'!$B$6:$B$90,A5,'Kế hoạch Task'!$K$6:$K$90,"Hoàn thành") -> 8 | F5: =COUNTIFS('Kế hoạch Task'!$B$6:$B$90,A5,'Kế hoạch Task'!$K$6:$K$90,"Đang làm") -> 0 | G5: =COUNTIFS('Kế hoạch Task'!$B$6:$B$90,A5,'Kế hoạch Task'!$K$6:$K$90,"Rủi ro") -> 0 | H5: =IF(D5=0,0,E5/D5) -> 1 | I5: 46190 | J5: 46191 | K5: Repo gmrag2, infra 9 services gồm Keycloak, Rust workspace, API health, frontend trang trống. | L5: ■ | M5: ■
A6: 2 | B6: Xác thực & ngữ cảnh tenant | C6: Định danh & Tenant | D6: =COUNTIF('Kế hoạch Task'!$B$6:$B$90,A6) -> 10 | E6: =COUNTIFS('Kế hoạch Task'!$B$6:$B$90,A6,'Kế hoạch Task'!$K$6:$K$90,"Hoàn thành") -> 10 | F6: =COUNTIFS('Kế hoạch Task'!$B$6:$B$90,A6,'Kế hoạch Task'!$K$6:$K$90,"Đang làm") -> 0 | G6: =COUNTIFS('Kế hoạch Task'!$B$6:$B$90,A6,'Kế hoạch Task'!$K$6:$K$90,"Rủi ro") -> 0 | H6: =IF(D6=0,0,E6/D6) -> 1 | I6: 46191 | J6: 46193 | K6: AuthUser từ Keycloak JWT, TenantContext, RLS cơ bản, provision user on first login, envelope lỗi. | M6: ■ | N6: ■ | O6: ■
A7: 3 | B7: Lược đồ dữ liệu & RLS đầy đủ | C7: Cơ sở dữ liệu | D7: =COUNTIF('Kế hoạch Task'!$B$6:$B$90,A7) -> 8 | E7: =COUNTIFS('Kế hoạch Task'!$B$6:$B$90,A7,'Kế hoạch Task'!$K$6:$K$90,"Hoàn thành") -> 8 | F7: =COUNTIFS('Kế hoạch Task'!$B$6:$B$90,A7,'Kế hoạch Task'!$K$6:$K$90,"Đang làm") -> 0 | G7: =COUNTIFS('Kế hoạch Task'!$B$6:$B$90,A7,'Kế hoạch Task'!$K$6:$K$90,"Rủi ro") -> 0 | H7: =IF(D7=0,0,E7/D7) -> 1 | I7: 46193 | J7: 46194 | K7: Migrations chính, seed script, test cô lập tenant âm tính. | O7: ■ | P7: ■
A8: 4 | B8: Tích hợp Qdrant | C8: Vector DB | D8: =COUNTIF('Kế hoạch Task'!$B$6:$B$90,A8) -> 7 | E8: =COUNTIFS('Kế hoạch Task'!$B$6:$B$90,A8,'Kế hoạch Task'!$K$6:$K$90,"Hoàn thành") -> 7 | F8: =COUNTIFS('Kế hoạch Task'!$B$6:$B$90,A8,'Kế hoạch Task'!$K$6:$K$90,"Đang làm") -> 0 | G8: =COUNTIFS('Kế hoạch Task'!$B$6:$B$90,A8,'Kế hoạch Task'!$K$6:$K$90,"Rủi ro") -> 0 | H8: =IF(D8=0,0,E8/D8) -> 1 | I8: 46194 | J8: 46195 | K8: QdrantStore wrapper, lifecycle collection, upsert/search chunks và graph. | P8: ■ | Q8: ■
A9: 5 | B9: Worker & pipeline ingestion | C9: Worker ingestion | D9: =COUNTIF('Kế hoạch Task'!$B$6:$B$90,A9) -> 10 | E9: =COUNTIFS('Kế hoạch Task'!$B$6:$B$90,A9,'Kế hoạch Task'!$K$6:$K$90,"Hoàn thành") -> 10 | F9: =COUNTIFS('Kế hoạch Task'!$B$6:$B$90,A9,'Kế hoạch Task'!$K$6:$K$90,"Đang làm") -> 0 | G9: =COUNTIFS('Kế hoạch Task'!$B$6:$B$90,A9,'Kế hoạch Task'!$K$6:$K$90,"Rủi ro") -> 0 | H9: =IF(D9=0,0,E9/D9) -> 1 | I9: 46195 | J9: 46197 | K9: Worker crate, S3, parser/OCR, chunking, embedding, graph extract, retry. | Q9: ■ | R9: ■ | S9: ■
A10: 6 | B10: Truy xuất RAG & LLM | C10: RAG & LLM | D10: =COUNTIF('Kế hoạch Task'!$B$6:$B$90,A10) -> 8 | E10: =COUNTIFS('Kế hoạch Task'!$B$6:$B$90,A10,'Kế hoạch Task'!$K$6:$K$90,"Hoàn thành") -> 8 | F10: =COUNTIFS('Kế hoạch Task'!$B$6:$B$90,A10,'Kế hoạch Task'!$K$6:$K$90,"Đang làm") -> 0 | G10: =COUNTIFS('Kế hoạch Task'!$B$6:$B$90,A10,'Kế hoạch Task'!$K$6:$K$90,"Rủi ro") -> 0 | H10: =IF(D10=0,0,E10/D10) -> 1 | I10: 46197 | J10: 46199 | K10: Provider trait, BYOK decrypt, retrieval chunks/graph, DeepSeek SSE, metering. | S10: ■ | T10: ■ | U10: ■
A11: 7 | B11: API tenant-scoped | C11: API nghiệp vụ | D11: =COUNTIF('Kế hoạch Task'!$B$6:$B$90,A11) -> 12 | E11: =COUNTIFS('Kế hoạch Task'!$B$6:$B$90,A11,'Kế hoạch Task'!$K$6:$K$90,"Hoàn thành") -> 12 | F11: =COUNTIFS('Kế hoạch Task'!$B$6:$B$90,A11,'Kế hoạch Task'!$K$6:$K$90,"Đang làm") -> 0 | G11: =COUNTIFS('Kế hoạch Task'!$B$6:$B$90,A11,'Kế hoạch Task'!$K$6:$K$90,"Rủi ro") -> 0 | H11: =IF(D11=0,0,E11/D11) -> 1 | I11: 46198 | J11: 46201 | K11: CRUD tenant/workspace/document/chat/graph, upload, enqueue, ACL filter. | T11: ■ | U11: ■ | V11: ■ | W11: ■
A12: 8 | B12: ResourceBAC & route ACL | C12: Phân quyền tài nguyên | D12: =COUNTIF('Kế hoạch Task'!$B$6:$B$90,A12) -> 7 | E12: =COUNTIFS('Kế hoạch Task'!$B$6:$B$90,A12,'Kế hoạch Task'!$K$6:$K$90,"Hoàn thành") -> 7 | F12: =COUNTIFS('Kế hoạch Task'!$B$6:$B$90,A12,'Kế hoạch Task'!$K$6:$K$90,"Đang làm") -> 0 | G12: =COUNTIFS('Kế hoạch Task'!$B$6:$B$90,A12,'Kế hoạch Task'!$K$6:$K$90,"Rủi ro") -> 0 | H12: =IF(D12=0,0,E12/D12) -> 1 | I12: 46200 | J12: 46202 | K12: check_permission, role hierarchy, grants, audit log, BYOK settings, usage. | V12: ■ | W12: ■ | X12: ■
A13: 9 | B13: Khung Frontend | C13: Frontend | D13: =COUNTIF('Kế hoạch Task'!$B$6:$B$90,A13) -> 9 | E13: =COUNTIFS('Kế hoạch Task'!$B$6:$B$90,A13,'Kế hoạch Task'!$K$6:$K$90,"Hoàn thành") -> 1 | F13: =COUNTIFS('Kế hoạch Task'!$B$6:$B$90,A13,'Kế hoạch Task'!$K$6:$K$90,"Đang làm") -> 0 | G13: =COUNTIFS('Kế hoạch Task'!$B$6:$B$90,A13,'Kế hoạch Task'!$K$6:$K$90,"Rủi ro") -> 0 | H13: =IF(D13=0,0,E13/D13) -> 0.11111111 | I13: 46199 | J13: 46202 | K13: Auth.js Keycloak provider, layout tenant/workspace, client wrappers, ChatPanel skeleton. | U13: ■ | V13: ■ | W13: ■ | X13: ■
A14: 10 | B14: Gia cố, kiểm thử & vận hành | C14: Kiểm thử & vận hành | D14: =COUNTIF('Kế hoạch Task'!$B$6:$B$90,A14) -> 6 | E14: =COUNTIFS('Kế hoạch Task'!$B$6:$B$90,A14,'Kế hoạch Task'!$K$6:$K$90,"Hoàn thành") -> 1 | F14: =COUNTIFS('Kế hoạch Task'!$B$6:$B$90,A14,'Kế hoạch Task'!$K$6:$K$90,"Đang làm") -> 0 | G14: =COUNTIFS('Kế hoạch Task'!$B$6:$B$90,A14,'Kế hoạch Task'!$K$6:$K$90,"Rủi ro") -> 0 | H14: =IF(D14=0,0,E14/D14) -> 0.16666667 | I14: 46202 | J14: 46203 | K14: E2E pass, negative isolation pass, README deploy, Qdrant/Postgres backup. | X14: ■ | Y14: ■

Sheet Rủi ro & Quyết định
A1: RỦI RO & QUYẾT ĐỊNH
A2: Tổng hợp quyết định kiến trúc và rủi ro cần quản trị trong quá trình build từ đầu.
A4: Quyết định kiến trúc
A5: ID | B5: Chủ đề | C5: Quyết định | D5: Lý do | E5: Tác động quản lý | F5: Sở hữu | G5: Ngày | H5: Trạng thái | I5: Liên quan | J5: Ghi chú
A6: D1 | B6: Định danh | C6: Keycloak self-host làm AuthN/OIDC; tenants vẫn DB-managed | D6: Bắt buộc self-host và vẫn giữ kiểm soát tenant/RLS trong DB | E6: Cần vận hành realm, client, redirect URI, SMTP/backup | F6: Backend Dev | G6: 46190 | H6: Đã chốt | I6: Sprint 1, 2, 9
A7: D2 | B7: Cô lập tenant | C7: TenantContext + SET LOCAL app.tenant_id + RLS | D7: Cô lập tenant ở DB | E7: Mọi query phải theo transaction context | F7: Backend Dev | G7: 46190 | H7: Đã chốt | I7: Sprint 2-3
A8: D3 | B8: Vector DB | C8: Qdrant collection-per-tenant | D8: Tách dữ liệu vector thật theo tenant | E8: Cần lifecycle tạo/xóa collection | F8: Backend Dev | G8: 46190 | H8: Đã chốt | I8: Sprint 4
A9: D4 | B9: Ingestion | C9: Redis + worker riêng | D9: Không block API, có retry/backoff | E9: Thêm độ phức tạp deploy | F9: Backend Dev | G9: 46190 | H9: Đã chốt | I9: Sprint 5
A10: D5 | B10: Embedding | C10: Ollama nomic-embed-text 768 mặc định; BYOK OpenAI tùy tenant | D10: Giảm chi phí mặc định, vẫn mở rộng | E10: Cần re-embed khi đổi dimension | F10: Backend Dev | G10: 46190 | H10: Đã chốt | I10: Sprint 5-6
A11: D6 | B11: Lưu trữ | C11: MinIO S3-compatible, không dùng local FS | D11: Dễ deploy và backup | E11: Cần init bucket và quy ước key | F11: Backend Dev | G11: 46190 | H11: Đã chốt | I11: Sprint 1, 5
A12: D7 | B12: Phân quyền tài nguyên (ReBAC) | C12: Zanzibar-style ReBAC native trên resource_acl (docs/5068.pdf); loại OPA/Rego + engine ngoài (OpenFGA/SpiceDB) | D12: Owner/editor/viewer + workspace-as-group + kế thừa đúng sweet-spot ReBAC; resource_acl đã là relation-tuple store; check chạy trong cùng RLS tx (không stale-ACL); không thêm service thứ 10 | E12: Cần namespace config + bounded check; MVP chỉ Check API (không zookies/Leopard/Expand); thêm cache nếu fan-out lớn
A14: Ma trận rủi ro
A15: ID | B15: Rủi ro | C15: Xác suất | D15: Ảnh hưởng | E15: Điểm | F15: Phương án giảm thiểu | G15: Chủ sở hữu | H15: Trạng thái | I15: Sprint liên quan | J15: Cập nhật mới nhất
A16: R1 | B16: Keycloak self-host tăng việc vận hành auth trong lịch 2 tuần | C16: Cao | D16: Cao | E16: =IF(C16="Cao",3,IF(C16="Trung bình",2,1))*IF(D16="Cao",3,IF(D16="Trung bình",2,1)) -> 9 | F16: Dùng 1 realm, 1 client, OIDC chuẩn; provision user on first login; giữ tenant/role/ACL trong DB | G16: Backend Dev | H16: Mở | I16: 1, 2, 9
A17: R2 | B17: Redis + worker làm tăng độ phức tạp deploy | C17: Trung bình | D17: Trung bình | E17: =IF(C17="Cao",3,IF(C17="Trung bình",2,1))*IF(D17="Cao",3,IF(D17="Trung bình",2,1)) -> 4 | F17: Healthcheck rõ, retry/backoff, README smoke test docker | G17: Backend Dev | H17: Mở | I17: 1, 5, 10
A18: R3 | B18: Collection-per-tenant có thể chạm giới hạn khi >10k tenant/node | C18: Thấp | D18: Cao | E18: =IF(C18="Cao",3,IF(C18="Trung bình",2,1))*IF(D18="Cao",3,IF(D18="Trung bình",2,1)) -> 3 | F18: Ghi rõ ngưỡng trong README; sharding cluster nằm ngoài MVP | G18: Backend Dev | H18: Chấp nhận | I18: 4, 10
A19: R4 | B19: Plan lớn trong 2 tuần, dễ mất nhịp TDD hoặc commit gộp | C19: Cao | D19: Cao | E19: =IF(C19="Cao",3,IF(C19="Trung bình",2,1))*IF(D19="Cao",3,IF(D19="Trung bình",2,1)) -> 9 | F19: Chạy theo sprint/task, commit riêng, dùng dashboard để khóa tiến độ và cắt scope nếu cần | G19: PM | H19: Mở | I19: Tất cả
A20: R5 | B20: Sai context tenant dẫn tới rò rỉ dữ liệu | C20: Trung bình | D20: Cao | E20: =IF(C20="Cao",3,IF(C20="Trung bình",2,1))*IF(D20="Cao",3,IF(D20="Trung bình",2,1)) -> 6 | F20: Negative test RLS, không bypass TenantContext, rà soát SQL có tenant_id | G20: Backend Dev | H20: Mở | I20: 2, 3, 10
A21: R6 | B21: BYOK embedding đổi dimension làm lệch dữ liệu Qdrant | C21: Trung bình | D21: Cao | E21: =IF(C21="Cao",3,IF(C21="Trung bình",2,1))*IF(D21="Cao",3,IF(D21="Trung bình",2,1)) -> 6 | F21: Đánh dấu cần re-embed document khi đổi provider/dimension | G21: Backend Dev | H21: Đang xử lý | I21: 5, 6
A22: R7 | B22: OCR PDF không ổn định trên tài liệu scan | C22: Trung bình | D22: Trung bình | E22: =IF(C22="Cao",3,IF(C22="Trung bình",2,1))*IF(D22="Cao",3,IF(D22="Trung bình",2,1)) -> 4 | F22: Timeout, fallback rõ, sample PDF test, log parser stage | G22: Backend Dev | H22: Mở | I22: 5
A23: R8 | B23: SSE DeepSeek stream/parser lỗi citation | C23: Trung bình | D23: Trung bình | E23: =IF(C23="Cao",3,IF(C23="Trung bình",2,1))*IF(D23="Cao",3,IF(D23="Trung bình",2,1)) -> 4 | F23: Port parser cũ kèm test token/citation | G23: Backend Dev | H23: Mở | I23: 6, 7
A24: R9 | B24: Đệ quy/fan-out của check ReBAC gây chậm khi nhiều grant hoặc nhóm lồng | C24: Thấp | D24: Trung bình | E24: =IF(C24="Cao",3,IF(C24="Trung bình",2,1))*IF(D24="Cao",3,IF(D24="Trung bình",2,1)) -> 2

Sheet RACI
A1: MA TRẬN RACI
A2: Phân vai theo team 3 người. R=Thực hiện, A=Chịu trách nhiệm cuối, C=Tư vấn, I=Cần biết.
A4: Hạng mục | B4: PM | C4: Backend Dev | D4: Frontend Dev | E4: Đầu ra kiểm soát | F4: Sheet theo dõi
A5: Hạ tầng & Monorepo | B5: I | C5: A/R | D5: C | E5: docker-compose, .env, healthcheck | F5: Timeline 2 tuần
A6: Xác thực & Tenant | B6: I | C6: A/R | D6: I | E6: TenantContext, RLS middleware | F6: Kế hoạch Task
A7: Schema & RLS | B7: I | C7: A/R | D7: I | E7: Migrations + negative tests | F7: Kế hoạch Task
A8: Qdrant | B8: I | C8: A/R | D8: I | E8: Collection lifecycle + search | F8: Kế hoạch Task
A9: Worker ingestion | B9: I | C9: A/R | D9: I | E9: PDF/chunk/embed/graph/save | F9: Kế hoạch Task
A10: RAG & LLM | B10: C | C10: A/R | D10: I | E10: Retrieval, prompt, citation, SSE | F10: Kế hoạch Task
A11: API tenant-scoped | B11: C | C11: A/R | D11: C | E11: Tenant-scoped CRUD + ACL | F11: Kế hoạch Task
A12: ResourceBAC & ACL | B12: C | C12: A/R | D12: C | E12: check_permission, grants, audit, BYOK settings | F12: Kế hoạch Task
A13: Khung Frontend | B13: C | C13: C | D13: A/R | E13: Layout, context, clients, mẫu component | F13: Kế hoạch Task
A14: Gia cố & nghiệm thu | B14: A | C14: R | D14: R | E14: E2E, pentest, smoke, backup | F14: Rủi ro & Quyết định

Sheet ResourceBAC
A1: RESOURCEBAC
A2: ReBAC kiểu Zanzibar (docs/5068.pdf) trên resource_acl như relation-tuple store. Ma trận dưới là tập quyền đề xuất; MVP hiện thực owner/editor/viewer (+ member = nhóm workspace).
A4: Ma trận quyền đề xuất | H4: Checklist rà soát T64-T68
A5: Vai trò/quyền | B5: Xem | C5: Bình luận | D5: Sửa | E5: Chia sẻ | F5: Xóa | H5: Mục | I5: Cần kiểm tra | J5: Trạng thái
A6: OWNER | B6: Có | C6: Có | D6: Có | E6: Có | F6: Có | H6: Tenant | I6: Mọi câu SQL có tenant_id hoặc chạy trong RLS context | J6: Hoàn thành
A7: ADMIN | B7: Có | C7: Có | D7: Có | E7: Có | F7: Có điều kiện | H7: Chủ sở hữu | I7: Owner luôn có quyền tối đa trong tài nguyên của mình | J7: Hoàn thành
A8: EDITOR | B8: Có | C8: Có | D8: Có | E8: Không | F8: Không | H8: ACL | I8: Grant theo resource_type/resource_id + principal_type/principal_id (user|workspace) | J8: Hoàn thành
A9: VIEWER | B9: Có | C9: Không | D9: Không | E9: Không | F9: Không | H9: Vai trò | I9: Quan hệ đồng tâm viewer ⊇ editor ⊇ owner + kế thừa workspace.member (userset rewrite) | J9: Hoàn thành
A10: ACL trực tiếp | B10: Theo grant | C10: Theo grant | D10: Theo grant | E10: Theo grant | F10: Không mặc định | H10: Audit | I10: Mọi thay đổi grant ghi audit_log | J10: Hoàn thành
A13: SQL mẫu kiểm tra quyền
A14: -- Mẫu logic cho rbac/check.rs — Zanzibar-style check_relation(object#relation@user). Xem docs/5068.pdf.
A15: -- object = (resource_type:resource_id); relation = resource_acl.permission (owner|editor|viewer);
A16: -- subject principal_type ∈ {user, workspace}. RLS (SET LOCAL app.tenant_id) lo cô lập tenant.
A17: SELECT (
A18: -- owner = cột owner của tài nguyên (documents.owner_id / chat_sessions.user_id)
A19: EXISTS (SELECT 1 FROM documents d WHERE d.id = $resource_id AND d.owner_id = $user)
A20: -- public share (chỉ documents)
A21: OR EXISTS (SELECT 1 FROM documents d WHERE d.id = $resource_id AND d.visibility = 'shared')
A22: -- grant trực tiếp (user) hoặc nhóm (workspace) trong resource_acl
A23: OR EXISTS (SELECT 1 FROM resource_acl a
A24: WHERE a.resource_type = $resource_type AND a.resource_id = $resource_id
... A32: ) AS allowed;

Sheet Thiết lập
A1: THIẾT LẬP & DANH MỤC
A2: Các danh mục dùng cho dropdown và các giả định lịch trình. Có thể sửa để phù hợp đội dự án.
A4: Thông số | B4: Giá trị | D4: Trạng thái | E4: TDD | F4: Ưu tiên | G4: Chủ sở hữu | H4: Mức rủi ro
A5: Ngày bắt đầu | B5: 46190 | D5: Chưa bắt đầu | E5: Chưa | F5: P0 - Chặn đường găng | G5: Backend Dev | H5: Thấp
A6: Ngày kết thúc | B6: 46203 | D6: Đang làm | E6: Đang làm | F6: P1 - Cao | G6: Frontend Dev | H6: Trung bình
A7: Độ dài kế hoạch | B7: 2 tuần / 14 ngày | D7: Rủi ro | E7: Hoàn tất | F7: P2 - Trung bình | G7: PM | H7: Cao
A8: Số luồng sprint gốc | B8: 10 | D8: Tạm dừng | E8: N/A
A9: Số task | B9: 82 | D9: Hoàn thành
A10: Đội thực thi | B10: PM + Backend Dev + Frontend Dev
A13: Tóm tắt kiến trúc từ plan
A14: Chủ đề | B14: Tóm tắt
A15: Kho mã | B15: Monorepo mới gmrag2/ gồm backend Rust, worker, frontend Next.js, infra docker-compose self-host.
A16: Định danh | B16: Keycloak self-host làm AuthN/OIDC; tenants và tenant_members vẫn tự quản lý trong PostgreSQL.
A17: Ngữ cảnh tenant | B17: Mọi request có X-Tenant-Id; backend validate membership và set SET LOCAL app.tenant_id.
A18: Vector DB | B18: Qdrant collection-per-tenant: chunks_{tenant_id} và graph_{tenant_id}.
A19: Hàng đợi | B19: Redis + worker riêng xử lý parse → chunk → embed → graph → save.
A20: Embedding | B20: Ollama nomic-embed-text 768 mặc định; BYOK OpenAI text-embedding-3-small khi cần.
A21: LLM | B21: DeepSeek deepseek-v4-flash mặc định; tenant override qua tenant_llm_config mã hóa AES-GCM.
A22: Lưu trữ | B22: MinIO S3-compatible cho PDF upload, key tenant_id/workspace_id/document_id.pdf.
A23: Ngoài phạm vi | B23: Billing/Stripe, k8s production manifests, migration dữ liệu từ GMRAG cũ, frontend chi tiết.
